Workbook
Name Slicer_Airports_in_Ireland: #N/A

Sheet About
A8: Table
A9: Code | B9: TAQ01
A10: Name | B10: Passengers
A11: Frequency | B11: Quarterly
A12: Last Updated | B12: 9/16/2025 11:00:00 AM
A13: Note
A14: Url | B14: https://ws.cso.ie/public/api.restful/PxStat.Data.Cube_API.ReadDataset/TAQ01/XLSX/2007/en
A16: Product
A17: Code | B17: AS
A18: Name | B18: Aviation Statistics
A20: Contacts
A21: Name | B21: Noreen Dorgan
A22: Email | B22: transport@cso.ie
A23: Phone | B23: (+353) 21 453 5260
A25: Copyright
A26: Code | B26: CSO
A27: Name | B27: Central Statistics Office, Ireland
A28: Url | B28: https://www.cso.ie/
A30: Properties
A31: Official Statistics | B31: Yes
A32: Exceptional | B32: No
A33: Archived | B33: No
A34: Analytical | B34: No
A35: Frontier Series | B35: No
A37: Language
A38: ISO Code | B38: en
A39: ISO Name | B39: English

Sheet  CLEANED_DATA
A1: Quarter (A) | B1: Airports in Ireland | C1: VALUE (B) | D1: Year | E1: Quarter_Num | F1: Period
A2: 2012Q1 | B2: All main airports | C2: 4546115 | D2: =VALUE(LEFT(A2,4)) -> 2012 | E2: =RIGHT(A2,2) -> Q1 | F2: =IF(D2<=2019,"Pre-COVID",IF(D2<=2021,"COVID","Post-COVID")) -> Pre-COVID
A3: 2012Q1 | B3: Cork | C3: 432766 | D3: =VALUE(LEFT(A3,4)) -> 2012 | E3: =RIGHT(A3,2) -> Q1 | F3: =IF(D3<=2019,"Pre-COVID",IF(D3<=2021,"COVID","Post-COVID")) -> Pre-COVID
A4: 2012Q1 | B4: Dublin | C4: 3740432 | D4: =VALUE(LEFT(A4,4)) -> 2012 | E4: =RIGHT(A4,2) -> Q1 | F4: =IF(D4<=2019,"Pre-COVID",IF(D4<=2021,"COVID","Post-COVID")) -> Pre-COVID
A5: 2012Q1 | B5: Kerry | C5: 49557 | D5: =VALUE(LEFT(A5,4)) -> 2012 | E5: =RIGHT(A5,2) -> Q1 | F5: =IF(D5<=2019,"Pre-COVID",IF(D5<=2021,"COVID","Post-COVID")) -> Pre-COVID
A6: 2012Q1 | B6: Knock | C6: 107936 | D6: =VALUE(LEFT(A6,4)) -> 2012 | E6: =RIGHT(A6,2) -> Q1 | F6: =IF(D6<=2019,"Pre-COVID",IF(D6<=2021,"COVID","Post-COVID")) -> Pre-COVID
A7: 2012Q1 | B7: Shannon | C7: 215424 | D7: =VALUE(LEFT(A7,4)) -> 2012 | E7: =RIGHT(A7,2) -> Q1 | F7: =IF(D7<=2019,"Pre-COVID",IF(D7<=2021,"COVID","Post-COVID")) -> Pre-COVID
A8: 2012Q2 | B8: All main airports | C8: 6478251 | D8: =VALUE(LEFT(A8,4)) -> 2012 | E8: =RIGHT(A8,2) -> Q2 | F8: =IF(D8<=2019,"Pre-COVID",IF(D8<=2021,"COVID","Post-COVID")) -> Pre-COVID | I8: {=_xlfn.UNIQUE($B$2:$B$100)} -> All main airports | L8: {=_xlfn.UNIQUE(B2:B325)} -> All main airports | M8: =N8 -> 396525211 | N8: =SUMIFS(C:C,B:B,B2) -> 396525211
A9: 2012Q2 | B9: Cork | C9: 648839 | D9: =VALUE(LEFT(A9,4)) -> 2012 | E9: =RIGHT(A9,2) -> Q2 | F9: =IF(D9<=2019,"Pre-COVID",IF(D9<=2021,"COVID","Post-COVID")) -> Pre-COVID | I9: Cork | L9: Cork | M9: =N9 -> 28819719 | N9: =SUMIFS(C:C,B:B,B3) -> 28819719
A10: 2012Q2 | B10: Dublin | C10: 5180478 | D10: =VALUE(LEFT(A10,4)) -> 2012 | E10: =RIGHT(A10,2) -> Q2 | F10: =IF(D10<=2019,"Pre-COVID",IF(D10<=2021,"COVID","Post-COVID")) -> Pre-COVID | I10: Dublin | L10: Dublin | M10: =N10 -> 335290263 | N10: =SUMIFS(C:C,B:B,B4) -> 335290263
A11: 2012Q2 | B11: Kerry | C11: 81536 | D11: =VALUE(LEFT(A11,4)) -> 2012 | E11: =RIGHT(A11,2) -> Q2 | F11: =IF(D11<=2019,"Pre-COVID",IF(D11<=2021,"COVID","Post-COVID")) -> Pre-COVID | I11: Kerry | L11: Kerry | M11: =N11 -> 4165947 | N11: =SUMIFS(C:C,B:B,B5) -> 4165947
A12: 2012Q2 | B12: Knock | C12: 199427 | D12: =VALUE(LEFT(A12,4)) -> 2012 | E12: =RIGHT(A12,2) -> Q2 | F12: =IF(D12<=2019,"Pre-COVID",IF(D12<=2021,"COVID","Post-COVID")) -> Pre-COVID | I12: Knock | L12: Knock | M12: =N12 -> 8904056 | N12: =SUMIFS(C:C,B:B,B6) -> 8904056
A13: 2012Q2 | B13: Shannon | C13: 367971 | D13: =VALUE(LEFT(A13,4)) -> 2012 | E13: =RIGHT(A13,2) -> Q2 | F13: =IF(D13<=2019,"Pre-COVID",IF(D13<=2021,"COVID","Post-COVID")) -> Pre-COVID | I13: Shannon | L13: Shannon | M13: =N13 -> 19345226 | N13: =SUMIFS(C:C,B:B,B7) -> 19345226
A14: 2012Q3 | B14: All main airports | C14: 7367068 | D14: =VALUE(LEFT(A14,4)) -> 2012 | E14: =RIGHT(A14,2) -> Q3 | F14: =IF(D14<=2019,"Pre-COVID",IF(D14<=2021,"COVID","Post-COVID")) -> Pre-COVID
A15: 2012Q3 | B15: Cork | C15: 754985 | D15: =VALUE(LEFT(A15,4)) -> 2012 | E15: =RIGHT(A15,2) -> Q3 | F15: =IF(D15<=2019,"Pre-COVID",IF(D15<=2021,"COVID","Post-COVID")) -> Pre-COVID
A16: 2012Q3 | B16: Dublin | C16: 5851043 | D16: =VALUE(LEFT(A16,4)) -> 2012 | E16: =RIGHT(A16,2) -> Q3 | F16: =IF(D16<=2019,"Pre-COVID",IF(D16<=2021,"COVID","Post-COVID")) -> Pre-COVID
A17: 2012Q3 | B17: Kerry | C17: 90438 | D17: =VALUE(LEFT(A17,4)) -> 2012 | E17: =RIGHT(A17,2) -> Q3 | F17: =IF(D17<=2019,"Pre-COVID",IF(D17<=2021,"COVID","Post-COVID")) -> Pre-COVID
A18: 2012Q3 | B18: Knock | C18: 230297 | D18: =VALUE(LEFT(A18,4)) -> 2012 | E18: =RIGHT(A18,2) -> Q3 | F18: =IF(D18<=2019,"Pre-COVID",IF(D18<=2021,"COVID","Post-COVID")) -> Pre-COVID
A19: 2012Q3 | B19: Shannon | C19: 440305 | D19: =VALUE(LEFT(A19,4)) -> 2012 | E19: =RIGHT(A19,2) -> Q3 | F19: =IF(D19<=2019,"Pre-COVID",IF(D19<=2021,"COVID","Post-COVID")) -> Pre-COVID
A20: 2012Q4 | B20: All main airports | C20: 5282939 | D20: =VALUE(LEFT(A20,4)) -> 2012 | E20: =RIGHT(A20,2) -> Q4 | F20: =IF(D20<=2019,"Pre-COVID",IF(D20<=2021,"COVID","Post-COVID")) -> Pre-COVID
A21: 2012Q4 | B21: Cork | C21: 497053 | D21: =VALUE(LEFT(A21,4)) -> 2012 | E21: =RIGHT(A21,2) -> Q4 | F21: =IF(D21<=2019,"Pre-COVID",IF(D21<=2021,"COVID","Post-COVID")) -> Pre-COVID
A22: 2012Q4 | B22: Dublin | C22: 4318828 | D22: =VALUE(LEFT(A22,4)) -> 2012 | E22: =RIGHT(A22,2) -> Q4 | F22: =IF(D22<=2019,"Pre-COVID",IF(D22<=2021,"COVID","Post-COVID")) -> Pre-COVID
A23: 2012Q4 | B23: Kerry | C23: 64911 | D23: =VALUE(LEFT(A23,4)) -> 2012 | E23: =RIGHT(A23,2) -> Q4 | F23: =IF(D23<=2019,"Pre-COVID",IF(D23<=2021,"COVID","Post-COVID")) -> Pre-COVID
A24: 2012Q4 | B24: Knock | C24: 139708 | D24: =VALUE(LEFT(A24,4)) -> 2012 | E24: =RIGHT(A24,2) -> Q4 | F24: =IF(D24<=2019,"Pre-COVID",IF(D24<=2021,"COVID","Post-COVID")) -> Pre-COVID
A25: 2012Q4 | B25: Shannon | C25: 262439 | D25: =VALUE(LEFT(A25,4)) -> 2012 | E25: =RIGHT(A25,2) -> Q4 | F25: =IF(D25<=2019,"Pre-COVID",IF(D25<=2021,"COVID","Post-COVID")) -> Pre-COVID
... A325: 2025Q2 | B325: Shannon | C325: 633511 | D325: =VALUE(LEFT(A325,4)) -> 2025 | E325: =RIGHT(A325,2) -> Q2 | F325: =IF(D325<=2019,"Pre-COVID",IF(D325<=2021,"COVID","Post-COVID")) -> Post-COVID

Sheet MASTER_DATA
A1: Statistic Label | B1: Quarter | C1: Airports in Ireland | D1: VALUE
A2: Passengers | B2: 2012Q1 | C2: All main airports | D2: 4546115
A3: Passengers | B3: 2012Q1 | C3: Cork | D3: 432766
A4: Passengers | B4: 2012Q1 | C4: Dublin | D4: 3740432
A5: Passengers | B5: 2012Q1 | C5: Kerry | D5: 49557
A6: Passengers | B6: 2012Q1 | C6: Knock | D6: 107936
A7: Passengers | B7: 2012Q1 | C7: Shannon | D7: 215424
A8: Passengers | B8: 2012Q2 | C8: All main airports | D8: 6478251
A9: Passengers | B9: 2012Q2 | C9: Cork | D9: 648839
A10: Passengers | B10: 2012Q2 | C10: Dublin | D10: 5180478
A11: Passengers | B11: 2012Q2 | C11: Kerry | D11: 81536
A12: Passengers | B12: 2012Q2 | C12: Knock | D12: 199427
A13: Passengers | B13: 2012Q2 | C13: Shannon | D13: 367971
... A325: Passengers | B325: 2025Q2 | C325: Shannon | D325: 633511

Sheet Dublin
A1: Quarter | B1: Airports in Ireland | C1: VALUE | D1: Year | E1: Quarter_Num | F1: Period
A2: 2012Q1 | B2: Dublin | C2: 3740432 | D2: 2012 | E2: Q1 | F2: Pre-COVID
A3: 2012Q2 | B3: Dublin | C3: 5180478 | D3: 2012 | E3: Q2 | F3: Pre-COVID
A4: 2012Q3 | B4: Dublin | C4: 5851043 | D4: 2012 | E4: Q3 | F4: Pre-COVID
A5: 2012Q4 | B5: Dublin | C5: 4318828 | D5: 2012 | E5: Q4 | F5: Pre-COVID
A6: 2013Q1 | B6: Dublin | C6: 3874988 | D6: 2013 | E6: Q1 | F6: Pre-COVID
A7: 2013Q2 | B7: Dublin | C7: 5460037 | D7: 2013 | E7: Q2 | F7: Pre-COVID
A8: 2013Q3 | B8: Dublin | C8: 6211891 | D8: 2013 | E8: Q3 | F8: Pre-COVID
A9: 2013Q4 | B9: Dublin | C9: 4601658 | D9: 2013 | E9: Q4 | F9: Pre-COVID
A10: 2014Q1 | B10: Dublin | C10: 4062698 | D10: 2014 | E10: Q1 | F10: Pre-COVID
A11: 2014Q2 | B11: Dublin | C11: 5914826 | D11: 2014 | E11: Q2 | F11: Pre-COVID
A12: 2014Q3 | B12: Dublin | C12: 6617238 | D12: 2014 | E12: Q3 | F12: Pre-COVID
A13: 2014Q4 | B13: Dublin | C13: 5100131 | D13: 2014 | E13: Q4 | F13: Pre-COVID
... A55: 2025Q2 | B55: Dublin | C55: 10017651 | D55: 2025 | E55: Q2 | F55: Post-COVID

Sheet Cork
A1: Quarter | B1: Airports in Ireland | C1: VALUE | D1: Year | E1: Quarter_Num | F1: Period
A2: 2012Q1 | B2: Cork | C2: 432766 | D2: 2012 | E2: Q1 | F2: Pre-COVID
A3: 2012Q2 | B3: Cork | C3: 648839 | D3: 2012 | E3: Q2 | F3: Pre-COVID
A4: 2012Q3 | B4: Cork | C4: 754985 | D4: 2012 | E4: Q3 | F4: Pre-COVID
A5: 2012Q4 | B5: Cork | C5: 497053 | D5: 2012 | E5: Q4 | F5: Pre-COVID
A6: 2013Q1 | B6: Cork | C6: 436568 | D6: 2013 | E6: Q1 | F6: Pre-COVID
A7: 2013Q2 | B7: Cork | C7: 634674 | D7: 2013 | E7: Q2 | F7: Pre-COVID
A8: 2013Q3 | B8: Cork | C8: 713739 | D8: 2013 | E8: Q3 | F8: Pre-COVID
A9: 2013Q4 | B9: Cork | C9: 467655 | D9: 2013 | E9: Q4 | F9: Pre-COVID
A10: 2014Q1 | B10: Cork | C10: 400785 | D10: 2014 | E10: Q1 | F10: Pre-COVID
A11: 2014Q2 | B11: Cork | C11: 610996 | D11: 2014 | E11: Q2 | F11: Pre-COVID
A12: 2014Q3 | B12: Cork | C12: 685538 | D12: 2014 | E12: Q3 | F12: Pre-COVID
A13: 2014Q4 | B13: Cork | C13: 440738 | D13: 2014 | E13: Q4 | F13: Pre-COVID
... A55: 2025Q2 | B55: Cork | C55: 993437 | D55: 2025 | E55: Q2 | F55: Post-COVID

Sheet Kerry
A1: Quarter | B1: Airports in Ireland | C1: VALUE | D1: Year | E1: Quarter_Num | F1: Period
A2: 2012Q1 | B2: Kerry | C2: 49557 | D2: 2012 | E2: Q1 | F2: Pre-COVID
A3: 2012Q2 | B3: Kerry | C3: 81536 | D3: 2012 | E3: Q2 | F3: Pre-COVID
A4: 2012Q3 | B4: Kerry | C4: 90438 | D4: 2012 | E4: Q3 | F4: Pre-COVID
A5: 2012Q4 | B5: Kerry | C5: 64911 | D5: 2012 | E5: Q4 | F5: Pre-COVID
A6: 2013Q1 | B6: Kerry | C6: 50391 | D6: 2013 | E6: Q1 | F6: Pre-COVID
A7: 2013Q2 | B7: Kerry | C7: 89225 | D7: 2013 | E7: Q2 | F7: Pre-COVID
A8: 2013Q3 | B8: Kerry | C8: 100314 | D8: 2013 | E8: Q3 | F8: Pre-COVID
A9: 2013Q4 | B9: Kerry | C9: 66112 | D9: 2013 | E9: Q4 | F9: Pre-COVID
A10: 2014Q1 | B10: Kerry | C10: 45956 | D10: 2014 | E10: Q1 | F10: Pre-COVID
A11: 2014Q2 | B11: Kerry | C11: 84394 | D11: 2014 | E11: Q2 | F11: Pre-COVID
A12: 2014Q3 | B12: Kerry | C12: 96963 | D12: 2014 | E12: Q3 | F12: Pre-COVID
A13: 2014Q4 | B13: Kerry | C13: 67642 | D13: 2014 | E13: Q4 | F13: Pre-COVID
... A55: 2025Q2 | B55: Kerry | C55: 126964 | D55: 2025 | E55: Q2 | F55: Post-COVID

Sheet Knock
A1: Quarter | B1: Airports in Ireland | C1: VALUE | D1: Year | E1: Quarter_Num | F1: Period
A2: 2020Q2 | B2: Knock | C2: 3 | D2: 2020 | E2: Q2 | F2: COVID
A3: 2021Q1 | B3: Knock | C3: 621 | D3: 2021 | E3: Q1 | F3: COVID
A4: 2021Q2 | B4: Knock | C4: 2079 | D4: 2021 | E4: Q2 | F4: COVID
A5: 2020Q4 | B5: Knock | C5: 7048 | D5: 2020 | E5: Q4 | F5: COVID
A6: 2020Q3 | B6: Knock | C6: 27513 | D6: 2020 | E6: Q3 | F6: COVID
A7: 2021Q3 | B7: Knock | C7: 69145 | D7: 2021 | E7: Q3 | F7: COVID
A8: 2022Q1 | B8: Knock | C8: 86381 | D8: 2022 | E8: Q1 | F8: Post-COVID
A9: 2014Q1 | B9: Knock | C9: 100116 | D9: 2014 | E9: Q1 | F9: Pre-COVID
A10: 2021Q4 | B10: Knock | C10: 102186 | D10: 2021 | E10: Q4 | F10: COVID
A11: 2012Q1 | B11: Knock | C11: 107936 | D11: 2012 | E11: Q1 | F11: Pre-COVID
A12: 2020Q1 | B12: Knock | C12: 107971 | D12: 2020 | E12: Q1 | F12: COVID
A13: 2013Q1 | B13: Knock | C13: 110780 | D13: 2013 | E13: Q1 | F13: Pre-COVID
... A55: 2025Q2 | B55: Knock | C55: 271057 | D55: 2025 | E55: Q2 | F55: Post-COVID

Sheet Shannon
A1: Quarter | B1: Airports in Ireland | C1: VALUE | D1: Year | E1: Quarter_Num | F1: Period
A2: 2012Q1 | B2: Shannon | C2: 215424 | D2: 2012 | E2: Q1 | F2: Pre-COVID
A3: 2012Q2 | B3: Shannon | C3: 367971 | D3: 2012 | E3: Q2 | F3: Pre-COVID
A4: 2012Q3 | B4: Shannon | C4: 440305 | D4: 2012 | E4: Q3 | F4: Pre-COVID
A5: 2012Q4 | B5: Shannon | C5: 262439 | D5: 2012 | E5: Q4 | F5: Pre-COVID
A6: 2013Q1 | B6: Shannon | C6: 203393 | D6: 2013 | E6: Q1 | F6: Pre-COVID
A7: 2013Q2 | B7: Shannon | C7: 373612 | D7: 2013 | E7: Q2 | F7: Pre-COVID
A8: 2013Q3 | B8: Shannon | C8: 466075 | D8: 2013 | E8: Q3 | F8: Pre-COVID
A9: 2013Q4 | B9: Shannon | C9: 265162 | D9: 2013 | E9: Q4 | F9: Pre-COVID
A10: 2014Q1 | B10: Shannon | C10: 194886 | D10: 2014 | E10: Q1 | F10: Pre-COVID
A11: 2014Q2 | B11: Shannon | C11: 468186 | D11: 2014 | E11: Q2 | F11: Pre-COVID
A12: 2014Q3 | B12: Shannon | C12: 559929 | D12: 2014 | E12: Q3 | F12: Pre-COVID
A13: 2014Q4 | B13: Shannon | C13: 332224 | D13: 2014 | E13: Q4 | F13: Pre-COVID
... A55: 2025Q2 | B55: Shannon | C55: 633511 | D55: 2025 | E55: Q2 | F55: Post-COVID

Sheet Chart
A1: Quarter | B1: Dublin | C1: Cork | D1: Kerry | E1: Knock | F1: Shannon | G1: Year | AM1: Airport | AN1: Mean_Passengers
A2: 2012Q1 | B2: 3740432 | C2: 432766 | D2: 49557 | E2: 3 | F2: 215424 | G2: =VALUE(LEFT(A2,4)) -> 2012 | AM2: Dublin | AN2: 6209078.9
A3: 2012Q2 | B3: 5180478 | C3: 648839 | D3: 81536 | E3: 621 | F3: 367971 | G3: =VALUE(LEFT(A3,4)) -> 2012 | AM3: Cork | AN3: 533698.5
A4: 2012Q3 | B4: 5851043 | C4: 754985 | D4: 90438 | E4: 2079 | F4: 440305 | G4: =VALUE(LEFT(A4,4)) -> 2012 | AM4: Kerry | AN4: 77147.167
A5: 2012Q4 | B5: 4318828 | C5: 497053 | D5: 64911 | E5: 7048 | F5: 262439 | G5: =VALUE(LEFT(A5,4)) -> 2012 | AM5: Knock | AN5: 164889.93
A6: 2013Q1 | B6: 3874988 | C6: 436568 | D6: 50391 | E6: 27513 | F6: 203393 | G6: =VALUE(LEFT(A6,4)) -> 2013 | AM6: Shannon | AN6: 358244.93
A7: 2013Q2 | B7: 5460037 | C7: 634674 | D7: 89225 | E7: 69145 | F7: 373612 | G7: =VALUE(LEFT(A7,4)) -> 2013
A8: 2013Q3 | B8: 6211891 | C8: 713739 | D8: 100314 | E8: 86381 | F8: 466075 | G8: =VALUE(LEFT(A8,4)) -> 2013
A9: 2013Q4 | B9: 4601658 | C9: 467655 | D9: 66112 | E9: 100116 | F9: 265162 | G9: =VALUE(LEFT(A9,4)) -> 2013
A10: 2014Q1 | B10: 4062698 | C10: 400785 | D10: 45956 | E10: 102186 | F10: 194886 | G10: =VALUE(LEFT(A10,4)) -> 2014
A11: 2014Q2 | B11: 5914826 | C11: 610996 | D11: 84394 | E11: 107936 | F11: 468186 | G11: =VALUE(LEFT(A11,4)) -> 2014
A12: 2014Q3 | B12: 6617238 | C12: 685538 | D12: 96963 | E12: 107971 | F12: 559929 | G12: =VALUE(LEFT(A12,4)) -> 2014
A13: 2014Q4 | B13: 5100131 | C13: 440738 | D13: 67642 | E13: 110780 | F13: 332224 | G13: =VALUE(LEFT(A13,4)) -> 2014
A14: 2015Q1 | B14: 4740924 | C14: 379553 | D14: 46806 | E14: 113413 | F14: 260625 | G14: =VALUE(LEFT(A14,4)) -> 2015
A15: 2015Q2 | B15: 6733056 | C15: 580130 | D15: 88309 | E15: 123034 | F15: 470946 | G15: =VALUE(LEFT(A15,4)) -> 2015
A16: 2015Q3 | B16: 7621339 | C16: 653801 | D16: 99683 | E16: 131234 | F16: 565509 | G16: =VALUE(LEFT(A16,4)) -> 2015
A17: 2015Q4 | B17: 5867199 | C17: 452194 | D17: 68241 | E17: 132657 | F17: 345808 | G17: =VALUE(LEFT(A17,4)) -> 2015
A18: 2016Q1 | B18: 5534979 | C18: 419334 | D18: 58771 | E18: 134221 | F18: 282929 | G18: =VALUE(LEFT(A18,4)) -> 2016
... A55: 2025Q2 | B55: 10017651 | C55: 993437 | D55: 126964 | E55: 271057 | F55: 633511 | G55: =VALUE(LEFT(A55,4)) -> 2025
B63: Airports | C63: Average of VALUE (B)
B64: COVID | C64: 726106.62
B65: All main airports | C65: 2178319.9
B66: Cork | C66: 97753.625
B67: Dublin | C67: 1941688.9
B68: Kerry | C68: 24794.625
B69: Knock | C69: 39570.75
B70: Shannon | C70: 74512
B71: Post-COVID | C71: 3165299
B72: All main airports | C72: 9495896.9
B73: Cork | C73: 696194.36
B74: Dublin | C74: 8045068.1
B75: Kerry | C75: 98627.643
... B85: Grand Total | C85: 2447686.5

Sheet Sheet1
A1: Quarter (A) | B1: Airports in Ireland | C1: VALUE (B) | D1: Year | E1: Quarter_Num | F1: Period | L1: Quarter | M1: Mean passenger | O1: VALUE (B) | P1: Year | Q1: Quarter_Num
A2: 2012Q1 | B2: All main airports | C2: 4546115 | D2: =VALUE(LEFT(A2,4)) -> 2012 | E2: =RIGHT(A2,2) -> Q1 | F2: =IF(D2<=2019,"Pre-COVID",IF(D2<=2021,"COVID","Post-COVID")) -> Pre-COVID | L2: Q1 | M2: =AVERAGEIFS(O2:O55,Q2:Q55,"Q1") -> 5866724.6 | O2: 4546115 | P2: 2012 | Q2: Q1
A3: 2012Q1 | B3: Cork | C3: 432766 | D3: =VALUE(LEFT(A3,4)) -> 2012 | E3: =RIGHT(A3,2) -> Q1 | F3: =IF(D3<=2019,"Pre-COVID",IF(D3<=2021,"COVID","Post-COVID")) -> Pre-COVID | L3: Q2 | M3: =AVERAGEIFS(O2:O55,Q2:Q55,"Q2") -> 7941135 | O3: 6478251 | P3: 2012 | Q3: Q2
A4: 2012Q1 | B4: Dublin | C4: 3740432 | D4: =VALUE(LEFT(A4,4)) -> 2012 | E4: =RIGHT(A4,2) -> Q1 | F4: =IF(D4<=2019,"Pre-COVID",IF(D4<=2021,"COVID","Post-COVID")) -> Pre-COVID | L4: Q3 | M4: =AVERAGEIFS(O2:O55,Q2:Q55,"Q3") -> 8873318.1 | O4: 7367068 | P4: 2012 | Q4: Q3
A5: 2012Q1 | B5: Kerry | C5: 49557 | D5: =VALUE(LEFT(A5,4)) -> 2012 | E5: =RIGHT(A5,2) -> Q1 | F5: =IF(D5<=2019,"Pre-COVID",IF(D5<=2021,"COVID","Post-COVID")) -> Pre-COVID | L5: Q4 | M5: =AVERAGEIFS(O2:O55,Q2:Q55,"Q4") -> 6758618.5 | O5: 5282939 | P5: 2012 | Q5: Q4
A6: 2012Q1 | B6: Knock | C6: 107936 | D6: =VALUE(LEFT(A6,4)) -> 2012 | E6: =RIGHT(A6,2) -> Q1 | F6: =IF(D6<=2019,"Pre-COVID",IF(D6<=2021,"COVID","Post-COVID")) -> Pre-COVID | O6: 4676120 | P6: 2013 | Q6: Q1
A7: 2012Q1 | B7: Shannon | C7: 215424 | D7: =VALUE(LEFT(A7,4)) -> 2012 | E7: =RIGHT(A7,2) -> Q1 | F7: =IF(D7<=2019,"Pre-COVID",IF(D7<=2021,"COVID","Post-COVID")) -> Pre-COVID | O7: 6747049 | P7: 2013 | Q7: Q2
A8: 2012Q2 | B8: All main airports | C8: 6478251 | D8: =VALUE(LEFT(A8,4)) -> 2012 | E8: =RIGHT(A8,2) -> Q2 | F8: =IF(D8<=2019,"Pre-COVID",IF(D8<=2021,"COVID","Post-COVID")) -> Pre-COVID | O8: 7719407 | P8: 2013 | Q8: Q3
A9: 2012Q2 | B9: Cork | C9: 648839 | D9: =VALUE(LEFT(A9,4)) -> 2012 | E9: =RIGHT(A9,2) -> Q2 | F9: =IF(D9<=2019,"Pre-COVID",IF(D9<=2021,"COVID","Post-COVID")) -> Pre-COVID | O9: 5538476 | P9: 2013 | Q9: Q4
A10: 2012Q2 | B10: Dublin | C10: 5180478 | D10: =VALUE(LEFT(A10,4)) -> 2012 | E10: =RIGHT(A10,2) -> Q2 | F10: =IF(D10<=2019,"Pre-COVID",IF(D10<=2021,"COVID","Post-COVID")) -> Pre-COVID | O10: 4804441 | P10: 2014 | Q10: Q1
A11: 2012Q2 | B11: Kerry | C11: 81536 | D11: =VALUE(LEFT(A11,4)) -> 2012 | E11: =RIGHT(A11,2) -> Q2 | F11: =IF(D11<=2019,"Pre-COVID",IF(D11<=2021,"COVID","Post-COVID")) -> Pre-COVID | O11: 7278735 | P11: 2014 | Q11: Q2
A12: 2012Q2 | B12: Knock | C12: 199427 | D12: =VALUE(LEFT(A12,4)) -> 2012 | E12: =RIGHT(A12,2) -> Q2 | F12: =IF(D12<=2019,"Pre-COVID",IF(D12<=2021,"COVID","Post-COVID")) -> Pre-COVID | O12: 8219084 | P12: 2014 | Q12: Q3
A13: 2012Q2 | B13: Shannon | C13: 367971 | D13: =VALUE(LEFT(A13,4)) -> 2012 | E13: =RIGHT(A13,2) -> Q2 | F13: =IF(D13<=2019,"Pre-COVID",IF(D13<=2021,"COVID","Post-COVID")) -> Pre-COVID | O13: 6084540 | P13: 2014 | Q13: Q4
A14: 2012Q3 | B14: All main airports | C14: 7367068 | D14: =VALUE(LEFT(A14,4)) -> 2012 | E14: =RIGHT(A14,2) -> Q3 | F14: =IF(D14<=2019,"Pre-COVID",IF(D14<=2021,"COVID","Post-COVID")) -> Pre-COVID | O14: 5541321 | P14: 2015 | Q14: Q1
A15: 2012Q3 | B15: Cork | C15: 754985 | D15: =VALUE(LEFT(A15,4)) -> 2012 | E15: =RIGHT(A15,2) -> Q3 | F15: =IF(D15<=2019,"Pre-COVID",IF(D15<=2021,"COVID","Post-COVID")) -> Pre-COVID | O15: 8072483 | P15: 2015 | Q15: Q2
A16: 2012Q3 | B16: Dublin | C16: 5851043 | D16: =VALUE(LEFT(A16,4)) -> 2012 | E16: =RIGHT(A16,2) -> Q3 | F16: =IF(D16<=2019,"Pre-COVID",IF(D16<=2021,"COVID","Post-COVID")) -> Pre-COVID | O16: 9166638 | P16: 2015 | Q16: Q3
A17: 2012Q3 | B17: Kerry | C17: 90438 | D17: =VALUE(LEFT(A17,4)) -> 2012 | E17: =RIGHT(A17,2) -> Q3 | F17: =IF(D17<=2019,"Pre-COVID",IF(D17<=2021,"COVID","Post-COVID")) -> Pre-COVID | O17: 6878352 | P17: 2015 | Q17: Q4
... A55: 2014Q1 | B55: Shannon | C55: 194886 | D55: =VALUE(LEFT(A55,4)) -> 2014 | E55: =RIGHT(A55,2) -> Q1 | F55: =IF(D55<=2019,"Pre-COVID",IF(D55<=2021,"COVID","Post-COVID")) -> Pre-COVID | O55: 12042620 | P55: 2025 | Q55: Q2
A56: 2014Q2 | B56: All main airports | C56: 7278735 | D56: =VALUE(LEFT(A56,4)) -> 2014 | E56: =RIGHT(A56,2) -> Q2 | F56: =IF(D56<=2019,"Pre-COVID",IF(D56<=2021,"COVID","Post-COVID")) -> Pre-COVID
A57: 2014Q2 | B57: Cork | C57: 610996 | D57: =VALUE(LEFT(A57,4)) -> 2014 | E57: =RIGHT(A57,2) -> Q2 | F57: =IF(D57<=2019,"Pre-COVID",IF(D57<=2021,"COVID","Post-COVID")) -> Pre-COVID
A58: 2014Q2 | B58: Dublin | C58: 5914826 | D58: =VALUE(LEFT(A58,4)) -> 2014 | E58: =RIGHT(A58,2) -> Q2 | F58: =IF(D58<=2019,"Pre-COVID",IF(D58<=2021,"COVID","Post-COVID")) -> Pre-COVID
A59: 2014Q2 | B59: Kerry | C59: 84394 | D59: =VALUE(LEFT(A59,4)) -> 2014 | E59: =RIGHT(A59,2) -> Q2 | F59: =IF(D59<=2019,"Pre-COVID",IF(D59<=2021,"COVID","Post-COVID")) -> Pre-COVID
A60: 2014Q2 | B60: Knock | C60: 200333 | D60: =VALUE(LEFT(A60,4)) -> 2014 | E60: =RIGHT(A60,2) -> Q2 | F60: =IF(D60<=2019,"Pre-COVID",IF(D60<=2021,"COVID","Post-COVID")) -> Pre-COVID
A61: 2014Q2 | B61: Shannon | C61: 468186 | D61: =VALUE(LEFT(A61,4)) -> 2014 | E61: =RIGHT(A61,2) -> Q2 | F61: =IF(D61<=2019,"Pre-COVID",IF(D61<=2021,"COVID","Post-COVID")) -> Pre-COVID
A62: 2014Q3 | B62: All main airports | C62: 8219084 | D62: =VALUE(LEFT(A62,4)) -> 2014 | E62: =RIGHT(A62,2) -> Q3 | F62: =IF(D62<=2019,"Pre-COVID",IF(D62<=2021,"COVID","Post-COVID")) -> Pre-COVID
A63: 2014Q3 | B63: Cork | C63: 685538 | D63: =VALUE(LEFT(A63,4)) -> 2014 | E63: =RIGHT(A63,2) -> Q3 | F63: =IF(D63<=2019,"Pre-COVID",IF(D63<=2021,"COVID","Post-COVID")) -> Pre-COVID
A64: 2014Q3 | B64: Dublin | C64: 6617238 | D64: =VALUE(LEFT(A64,4)) -> 2014 | E64: =RIGHT(A64,2) -> Q3 | F64: =IF(D64<=2019,"Pre-COVID",IF(D64<=2021,"COVID","Post-COVID")) -> Pre-COVID
A65: 2014Q3 | B65: Kerry | C65: 96963 | D65: =VALUE(LEFT(A65,4)) -> 2014 | E65: =RIGHT(A65,2) -> Q3 | F65: =IF(D65<=2019,"Pre-COVID",IF(D65<=2021,"COVID","Post-COVID")) -> Pre-COVID
A66: 2014Q3 | B66: Knock | C66: 259416 | D66: =VALUE(LEFT(A66,4)) -> 2014 | E66: =RIGHT(A66,2) -> Q3 | F66: =IF(D66<=2019,"Pre-COVID",IF(D66<=2021,"COVID","Post-COVID")) -> Pre-COVID
A67: 2014Q3 | B67: Shannon | C67: 559929 | D67: =VALUE(LEFT(A67,4)) -> 2014 | E67: =RIGHT(A67,2) -> Q3 | F67: =IF(D67<=2019,"Pre-COVID",IF(D67<=2021,"COVID","Post-COVID")) -> Pre-COVID
... A325: 2025Q2 | B325: Shannon | C325: 633511 | D325: =VALUE(LEFT(A325,4)) -> 2025 | E325: =RIGHT(A325,2) -> Q2 | F325: =IF(D325<=2019,"Pre-COVID",IF(D325<=2021,"COVID","Post-COVID")) -> Post-COVID

Sheet Descriptive_Stats
AK1: Quarter | AL1: Dublin | AM1: Cork | AN1: Kerry | AO1: Knock | AP1: Shannon | AQ1: Year | AV1: Q1 | AW1: Q2 | AX1: Q3 | AY1: Q4
AK2: 2012Q1 | AL2: 3740432 | AM2: 432766 | AN2: 49557 | AO2: 3 | AP2: 215424 | AQ2: =VALUE(LEFT(AK2,4)) -> 2012 | AR2: =IF(AQ2<=2019,"Pre-COVID",IF(AQ2<=2021,"COVID","Post-COVID")) -> Pre-COVID | AV2: 4546115 | AW2: 6478251 | AX2: 7367068 | AY2: 5282939
A3: MEAN OF EACH AIRPORT: | B3: Value | E3: MEDIAN OF EACH AIRPORT | K3: STANDARD DEVIATION OF EACH AIRPORT | S3: COUNT (NUMBER OF QUARTERS IN AIRPORT) | AK3: 2012Q2 | AL3: 5180478 | AM3: 648839 | AN3: 81536 | AO3: 621 | AP3: 367971 | AQ3: =VALUE(LEFT(AK3,4)) -> 2012 | AR3: =IF(AQ3<=2019,"Pre-COVID",IF(AQ3<=2021,"COVID","Post-COVID")) -> Pre-COVID | AV3: 4676120 | AW3: 6747049 | AX3: 7719407 | AY3: 5538476
A4: Dublin | B4: =AVERAGE(Dublin!C2:C55) -> 6209078.9 | F4: Dublin | G4: =MEDIAN(Dublin!C2:C55) -> 6535140 | L4: Dublin | M4: =_xlfn.STDEV.S(Dublin!C2:C160) -> 2545649 | U4: Dublin | V4: =COUNT(Dublin!C2:C160) -> 54 | AK4: 2012Q3 | AL4: 5851043 | AM4: 754985 | AN4: 90438 | AO4: 2079 | AP4: 440305 | AQ4: =VALUE(LEFT(AK4,4)) -> 2012 | AR4: =IF(AQ4<=2019,"Pre-COVID",IF(AQ4<=2021,"COVID","Post-COVID")) -> Pre-COVID | AV4: 4804441 | AW4: 7278735 | AX4: 8219084 | AY4: 6084540
A5: Cork | B5: =AVERAGE(Cork!C2:C55) -> 533698.5 | F5: Cork | G5: =MEDIAN(Cork!C2:C160) -> 565276.5 | L5: Cork | M5: =_xlfn.STDEV.S(Cork!C2:C160) -> 240056.81 | U5: Cork | V5: =COUNT(Cork!C2:C160) -> 54 | AK5: 2012Q4 | AL5: 4318828 | AM5: 497053 | AN5: 64911 | AO5: 7048 | AP5: 262439 | AQ5: =VALUE(LEFT(AK5,4)) -> 2012 | AR5: =IF(AQ5<=2019,"Pre-COVID",IF(AQ5<=2021,"COVID","Post-COVID")) -> Pre-COVID | AV5: 5541321 | AW5: 8072483 | AX5: 9166638 | AY5: 6878352
A6: Kerry | B6: =AVERAGE(Kerry!C2:C55) -> 77147.167 | F6: Kerry | G6: =MEDIAN(Kerry!C2:C55) -> 81904.5 | L6: Kerry | M6: =_xlfn.STDEV.S(Kerry!C2:C160) -> 32426.674 | U6: Kerry | V6: =COUNT(Kerry!C2:C160) -> 54 | AK6: 2013Q1 | AL6: 3874988 | AM6: 436568 | AN6: 50391 | AO6: 27513 | AP6: 203393 | AQ6: =VALUE(LEFT(AK6,4)) -> 2013 | AR6: =IF(AQ6<=2019,"Pre-COVID",IF(AQ6<=2021,"COVID","Post-COVID")) -> Pre-COVID | AV6: 6419047 | AW6: 8814289 | AX6: 9989845 | AY6: 7518046
A7: Knock | B7: =AVERAGE(Knock!C2:C55) -> 164889.93 | F7: Knock | G7: =MEDIAN(Knock!C2:C55) -> 170526 | L7: Knock | M7: =_xlfn.STDEV.S(Knock!C2:C160) -> 72890.87 | U7: Knock | V7: =COUNT(Knock!C2:C160) -> 54 | AK7: 2013Q2 | AL7: 5460037 | AM7: 634674 | AN7: 89225 | AO7: 69145 | AP7: 373612 | AQ7: =VALUE(LEFT(AK7,4)) -> 2013 | AR7: =IF(AQ7<=2019,"Pre-COVID",IF(AQ7<=2021,"COVID","Post-COVID")) -> Pre-COVID | AV7: 6678744 | AW7: 9359711 | AX7: 10524366 | AY7: 7876478
A8: Shannon | B8: =AVERAGE(Shannon!C2:C55) -> 358244.93 | F8: Shannon | G8: =MEDIAN(Shannon!C2:C160) -> 367871 | L8: Shannon | M8: =_xlfn.STDEV.S(Shannon!C2:C160) -> 168868.01 | U8: Shannon | V8: =COUNT(Shannon!C2:C160) -> 54 | AK8: 2013Q3 | AL8: 6211891 | AM8: 713739 | AN8: 100314 | AO8: 86381 | AP8: 466075 | AQ8: =VALUE(LEFT(AK8,4)) -> 2013 | AR8: =IF(AQ8<=2019,"Pre-COVID",IF(AQ8<=2021,"COVID","Post-COVID")) -> Pre-COVID | AV8: 6939843 | AW8: 10031143 | AX8: 11131101 | AY8: 8419046
AK9: 2013Q4 | AL9: 4601658 | AM9: 467655 | AN9: 66112 | AO9: 100116 | AP9: 265162 | AQ9: =VALUE(LEFT(AK9,4)) -> 2013 | AR9: =IF(AQ9<=2019,"Pre-COVID",IF(AQ9<=2021,"COVID","Post-COVID")) -> Pre-COVID | AV9: 7435673 | AW9: 10479523 | AX9: 11597270 | AY9: 8540952
AK10: 2014Q1 | AL10: 4062698 | AM10: 400785 | AN10: 45956 | AO10: 102186 | AP10: 194886 | AQ10: =VALUE(LEFT(AK10,4)) -> 2014 | AR10: =IF(AQ10<=2019,"Pre-COVID",IF(AQ10<=2021,"COVID","Post-COVID")) -> Pre-COVID | AV10: 5916477 | AW10: 164402 | AX10: 1453684 | AY10: 759119
AK11: 2014Q2 | AL11: 5914826 | AM11: 610996 | AN11: 84394 | AO11: 107936 | AP11: 468186 | AQ11: =VALUE(LEFT(AK11,4)) -> 2014 | AR11: =IF(AQ11<=2019,"Pre-COVID",IF(AQ11<=2021,"COVID","Post-COVID")) -> Pre-COVID | AV11: 418969 | AW11: 596349 | AX11: 3576508 | AY11: 4541051
AK12: 2014Q3 | AL12: 6617238 | AM12: 685538 | AN12: 96963 | AO12: 107971 | AP12: 559929 | AQ12: =VALUE(LEFT(AK12,4)) -> 2014 | AR12: =IF(AQ12<=2019,"Pre-COVID",IF(AQ12<=2021,"COVID","Post-COVID")) -> Pre-COVID | AV12: 4700322 | AW12: 9134970 | AX12: 10444239 | AY12: 8238809
AK13: 2014Q4 | AL13: 5100131 | AM13: 440738 | AN13: 67642 | AO13: 110780 | AP13: 332224 | AQ13: =VALUE(LEFT(AK13,4)) -> 2014 | AR13: =IF(AQ13<=2019,"Pre-COVID",IF(AQ13<=2021,"COVID","Post-COVID")) -> Pre-COVID | AV13: 7622484 | AW13: 10744701 | AX13: 11799615 | AY13: 9019601
AK14: 2015Q1 | AL14: 4740924 | AM14: 379553 | AN14: 46806 | AO14: 113413 | AP14: 260625 | AQ14: =VALUE(LEFT(AK14,4)) -> 2015 | AR14: =IF(AQ14<=2019,"Pre-COVID",IF(AQ14<=2021,"COVID","Post-COVID")) -> Pre-COVID | AV14: 8227159 | AW14: 11231664 | AX14: 12364310 | AY14: 9164632
AK15: 2015Q2 | AL15: 6733056 | AM15: 580130 | AN15: 88309 | AO15: 123034 | AP15: 470946 | AQ15: =VALUE(LEFT(AK15,4)) -> 2015 | AR15: =IF(AQ15<=2019,"Pre-COVID",IF(AQ15<=2021,"COVID","Post-COVID")) -> Pre-COVID | AV15: 8207430 | AW15: 12042620
A16: MAXIMUM NUMBER OF PASSENGERS W.R.T QUARTER IN EACH AIRPORT | L16: MINIMUM NUMBER OF PASSENGERS W.R.T QUARTER IN EACH AIRPORT | X16: RANGE OF EACH AIRPORT | AK16: 2015Q3 | AL16: 7621339 | AM16: 653801 | AN16: 99683 | AO16: 131234 | AP16: 565509 | AQ16: =VALUE(LEFT(AK16,4)) -> 2015 | AR16: =IF(AQ16<=2019,"Pre-COVID",IF(AQ16<=2021,"COVID","Post-COVID")) -> Pre-COVID
B17: Dublin | C17: =MAX(Dublin!C2:C160) -> 10369522 | D17: 2024 | E17: Q3 | N17: Dublin | O17: =MIN(Dublin!C2:C160) -> 155592 | P17: 2020 | Q17: Q2 | X17: Dublin | Y17: =C17-O17 -> 10213930 | AK17: 2015Q4 | AL17: 5867199 | AM17: 452194 | AN17: 68241 | AO17: 132657 | AP17: 345808 | AQ17: =VALUE(LEFT(AK17,4)) -> 2015 | AR17: =IF(AQ17<=2019,"Pre-COVID",IF(AQ17<=2021,"COVID","Post-COVID")) -> Pre-COVID
B18: Cork | C18: =MAX(Cork!C2:C160) -> 993437 | D18: 2025 | E18: Q2 | N18: Cork | O18: =MIN(Cork!C2:C160) -> 7879 | P18: 2020 | Q18: Q2 | X18: Cork | Y18: =C18-O18 -> 985558 | AK18: 2016Q1 | AL18: 5534979 | AM18: 419334 | AN18: 58771 | AO18: 134221 | AP18: 282929 | AQ18: =VALUE(LEFT(AK18,4)) -> 2016 | AR18: =IF(AQ18<=2019,"Pre-COVID",IF(AQ18<=2021,"COVID","Post-COVID")) -> Pre-COVID
B19: Kerry | C19: =MAX(Kerry!C2:C160) -> 135505 | D19: 2024 | E19: Q3 | N19: Kerry | O19: =MIN(Kerry!C2:C160) -> 808 | P19: 2020 | Q19: Q2 | X19: Kerry | Y19: =C19-O19 -> 134697 | AK19: 2016Q2 | AL19: 7415559 | AM19: 625599 | AN19: 91072 | AO19: 137889 | AP19: 481657 | AQ19: =VALUE(LEFT(AK19,4)) -> 2016 | AR19: =IF(AQ19<=2019,"Pre-COVID",IF(AQ19<=2021,"COVID","Post-COVID")) -> Pre-COVID
B20: Knock | C20: =MAX(Knock!C2:C160) -> 271057 | D20: 2025 | E20: Q2 | N20: Knock | O20: =MIN(Knock!C2:C160) -> 3 | P20: 2020 | Q20: Q2 | X20: Knock | Y20: =C20-O20 -> 271054 | AK20: 2016Q3 | AL20: 8361602 | AM20: 706690 | AN20: 104956 | AO20: 139708 | AP20: 562727 | AQ20: =VALUE(LEFT(AK20,4)) -> 2016 | AR20: =IF(AQ20<=2019,"Pre-COVID",IF(AQ20<=2021,"COVID","Post-COVID")) -> Pre-COVID
B21: Shannon | C21: =MAX(Shannon!C2:C160) -> 642440 | D21: 2024 | E21: Q3 | N21: Shannon | O21: =MIN(Shannon!C2:C160) -> 120 | P21: 2020 | Q21: Q2 | X21: Shannon | Y21: =C21-O21 -> 642320 | AK21: 2016Q4 | AL21: 6466748 | AM21: 474610 | AN21: 70871 | AO21: 142569 | AP21: 347254 | AQ21: =VALUE(LEFT(AK21,4)) -> 2016 | AR21: =IF(AQ21<=2019,"Pre-COVID",IF(AQ21<=2021,"COVID","Post-COVID")) -> Pre-COVID
AK22: 2017Q1 | AL22: 5795278 | AM22: 418458 | AN22: 59034 | AO22: 143805 | AP22: 271753 | AQ22: =VALUE(LEFT(AK22,4)) -> 2017 | AR22: =IF(AQ22<=2019,"Pre-COVID",IF(AQ22<=2021,"COVID","Post-COVID")) -> Pre-COVID
AK23: 2017Q2 | AL23: 7960058 | AM23: 637491 | AN23: 98536 | AO23: 144910 | AP23: 454971 | AQ23: =VALUE(LEFT(AK23,4)) -> 2017 | AR23: =IF(AQ23<=2019,"Pre-COVID",IF(AQ23<=2021,"COVID","Post-COVID")) -> Pre-COVID
AK24: 2017Q3 | AL24: 8893941 | AM24: 752138 | AN24: 102166 | AO24: 158563 | AP24: 531272 | AQ24: =VALUE(LEFT(AK24,4)) -> 2017 | AR24: =IF(AQ24<=2019,"Pre-COVID",IF(AQ24<=2021,"COVID","Post-COVID")) -> Pre-COVID
AK25: 2017Q4 | AL25: 6805197 | AM25: 493363 | AN25: 75744 | AO25: 158595 | AP25: 341394 | AQ25: =VALUE(LEFT(AK25,4)) -> 2017 | AR25: =IF(AQ25<=2019,"Pre-COVID",IF(AQ25<=2021,"COVID","Post-COVID")) -> Pre-COVID
AK26: 2018Q1 | AL26: 6037482 | AM26: 428618 | AN26: 65439 | AO26: 160780 | AP26: 277070 | AQ26: =VALUE(LEFT(AK26,4)) -> 2018 | AR26: =IF(AQ26<=2019,"Pre-COVID",IF(AQ26<=2021,"COVID","Post-COVID")) -> Pre-COVID
C27: LOWER QUARTILE FOR EACH AIRPORT | L27: UPPER QUARTILE FOR EACH AIRPORT | U27: INTERQUARTILE RANGE | AK27: 2018Q2 | AL27: 8558244 | AM27: 665643 | AN27: 103617 | AO27: 168444 | AP27: 486168 | AQ27: =VALUE(LEFT(AK27,4)) -> 2018 | AR27: =IF(AQ27<=2019,"Pre-COVID",IF(AQ27<=2021,"COVID","Post-COVID")) -> Pre-COVID
U28: Dublin | V28: =N32-C32 -> 2941285 | AK28: 2018Q3 | AL28: 9430981 | AM28: 773012 | AN28: 114010 | AO28: 170516 | AP28: 561411 | AQ28: =VALUE(LEFT(AK28,4)) -> 2018 | AR28: =IF(AQ28<=2019,"Pre-COVID",IF(AQ28<=2021,"COVID","Post-COVID")) -> Pre-COVID
C29: 25% of the data falls below this value | M29: 75% of the data falls below this value | U29: Cork | V29: =N33-C33 -> 252201.5 | AK29: 2018Q4 | AL29: 7292712 | AM29: 520533 | AN29: 82273 | AO29: 170536 | AP29: 353012 | AQ29: =VALUE(LEFT(AK29,4)) -> 2018 | AR29: =IF(AQ29<=2019,"Pre-COVID",IF(AQ29<=2021,"COVID","Post-COVID")) -> Pre-COVID
U30: Kerry | V30: =N34-C34 -> 39960 | AK30: 2019Q1 | AL30: 6480314 | AM30: 474297 | AN30: 68606 | AO30: 180453 | AP30: 269887 | AQ30: =VALUE(LEFT(AK30,4)) -> 2019 | AR30: =IF(AQ30<=2019,"Pre-COVID",IF(AQ30<=2021,"COVID","Post-COVID")) -> Pre-COVID
U31: Knock | V31: =N35-C35 -> 100253.75 | AK31: 2019Q2 | AL31: 8957586 | AM31: 728548 | AN31: 102534 | AO31: 182254 | AP31: 468422 | AQ31: =VALUE(LEFT(AK31,4)) -> 2019 | AR31: =IF(AQ31<=2019,"Pre-COVID",IF(AQ31<=2021,"COVID","Post-COVID")) -> Pre-COVID
B32: Dublin | C32: =_xlfn.QUARTILE.INC(Dublin!C2:C55,1) -> 4830725.8 | M32: Dublin | N32: =_xlfn.QUARTILE.INC(Dublin!C2:C55,3) -> 7772010.8 | U32: Shannon | V32: =N36-C36 -> 207195.25 | AK32: 2019Q3 | AL32: 9852369 | AM32: 832198 | AN32: 116018 | AO32: 189501 | AP32: 536697 | AQ32: =VALUE(LEFT(AK32,4)) -> 2019 | AR32: =IF(AQ32<=2019,"Pre-COVID",IF(AQ32<=2021,"COVID","Post-COVID")) -> Pre-COVID
B33: Cork | C33: =_xlfn.QUARTILE.INC(Cork!C2:C55,1) -> 429655 | M33: Cork | N33: =_xlfn.QUARTILE.INC(Cork!C2:C55,3) -> 681856.5 | AK33: 2019Q4 | AL33: 7385982 | AM33: 550423 | AN33: 82678 | AO33: 190172 | AP33: 341416 | AQ33: =VALUE(LEFT(AK33,4)) -> 2019 | AR33: =IF(AQ33<=2019,"Pre-COVID",IF(AQ33<=2021,"COVID","Post-COVID")) -> Pre-COVID
B34: Kerry | C34: =_xlfn.QUARTILE.INC(Kerry!C2:C55,1) -> 60196.25 | M34: Kerry | N34: =_xlfn.QUARTILE.INC(Kerry!C2:C55,3) -> 100156.25 | AK34: 2020Q1 | AL34: 5139128 | AM34: 397387 | AN34: 55763 | AO34: 199427 | AP34: 216228 | AQ34: =VALUE(LEFT(AK34,4)) -> 2020 | AR34: =IF(AQ34<=2019,"Pre-COVID",IF(AQ34<=2021,"COVID","Post-COVID")) -> COVID
B35: Knock | C35: =_xlfn.QUARTILE.INC(Knock!C2:C55,1) -> 125084 | M35: Knock | N35: =_xlfn.QUARTILE.INC(Knock!C2:C55,3) -> 225337.75 | AK35: 2020Q2 | AL35: 155592 | AM35: 7879 | AN35: 808 | AO35: 200028 | AP35: 120 | AQ35: =VALUE(LEFT(AK35,4)) -> 2020 | AR35: =IF(AQ35<=2019,"Pre-COVID",IF(AQ35<=2021,"COVID","Post-COVID")) -> COVID
B36: Shannon | C36: =_xlfn.QUARTILE.INC(Shannon!C2:C55,1) -> 263119.75 | M36: Shannon | N36: =_xlfn.QUARTILE.INC(Shannon!C2:C55,3) -> 470315 | AK36: 2020Q3 | AL36: 1270411 | AM36: 90287 | AN36: 19968 | AO36: 200042 | AP36: 45505 | AQ36: =VALUE(LEFT(AK36,4)) -> 2020 | AR36: =IF(AQ36<=2019,"Pre-COVID",IF(AQ36<=2021,"COVID","Post-COVID")) -> COVID
AK37: 2020Q4 | AL37: 702109 | AM37: 31461 | AN37: 6420 | AO37: 200333 | AP37: 12081 | AQ37: =VALUE(LEFT(AK37,4)) -> 2020 | AR37: =IF(AQ37<=2019,"Pre-COVID",IF(AQ37<=2021,"COVID","Post-COVID")) -> COVID
AK38: 2021Q1 | AL38: 405112 | AM38: 8926 | AN38: 1988 | AO38: 200402 | AP38: 2322 | AQ38: =VALUE(LEFT(AK38,4)) -> 2021 | AR38: =IF(AQ38<=2019,"Pre-COVID",IF(AQ38<=2021,"COVID","Post-COVID")) -> COVID
AK39: 2021Q2 | AL39: 554749 | AM39: 24931 | AN39: 4301 | AO39: 208655 | AP39: 10289 | AQ39: =VALUE(LEFT(AK39,4)) -> 2021 | AR39: =IF(AQ39<=2019,"Pre-COVID",IF(AQ39<=2021,"COVID","Post-COVID")) -> COVID
AK40: 2021Q3 | AL40: 3202834 | AM40: 133809 | AN40: 45426 | AO40: 217471 | AP40: 125294 | AQ40: =VALUE(LEFT(AK40,4)) -> 2021 | AR40: =IF(AQ40<=2019,"Pre-COVID",IF(AQ40<=2021,"COVID","Post-COVID")) -> COVID
...

Sheet Confidence_Interval
A1: Confidence Interval for Mean Quarterly Passengers - Dublin | N1: Confidence Interval for Mean Quarterly Passengers - Cork
A3: Sample Size | B3: n | C3: =COUNT(Dublin!C2:C55) -> 54 | N3: Sample Size | O3: n | P3: =COUNT(Cork!C2:C55) -> 54
A4: PE | B4: x bar | C4: =AVERAGE(Dublin!C2:C55) -> 6209078.9 | J4: SE | K4: Standard Error | N4: PE | O4: x bar | P4: =AVERAGE(Cork!C2:C55) -> 533698.5
A5: Pop Stdev | B5: 𝜎 | C5: =_xlfn.STDEV.S(Dublin!C2:C55) -> 2545649 | J5: ME | K5: Margin of Error | N5: Pop Stdev | O5: 𝜎 | P5: =_xlfn.STDEV.S(Cork!C2:C55) -> 240056.81
J6: PE | K6: Point Estimate
J7: LL | K7: Lower Limit
J8: UL | K8: Uper Limit
G10: Confidence Interval (CI) | T10: Confidence Interval (CI)
A11: 𝛼 | B11: CL (1- 𝛼) | C11: z_𝛼/2 | D11: SE | E11: PE | F11: ME | G11: LL | H11: UL | N11: 𝛼 | O11: CL (1- 𝛼) | P11: z_𝛼/2 | Q11: SE | R11: PE | S11: ME | T11: LL | U11: UL
A12: 0.1 | B12: =1-A12 -> 0.9 | C12: =_xlfn.NORM.S.INV(A12/2) -> -1.6448536 | D12: =$C$5/SQRT($C$3) -> 346418.95 | E12: =$C$4 -> 6209078.9 | F12: =ABS(C12*D12) -> 569808.46 | G12: =E12-F12 -> 5639270.5 | H12: =E12+F12 -> 6778887.4 | N12: 0.1 | O12: =1-N12 -> 0.9 | P12: =_xlfn.NORM.S.INV(N12/2) -> -1.6448536 | Q12: =$P$5/SQRT($P$3) -> 32667.594 | R12: =$P$4 -> 533698.5 | S12: =ABS(P12*Q12) -> 53733.41 | T12: =R12-S12 -> 479965.09 | U12: =R12+S12 -> 587431.91
A13: 0.05 | B13: =1-A13 -> 0.95 | C13: =_xlfn.NORM.S.INV(A13/2) -> -1.959964 | D13: =$C$5/SQRT($C$3) -> 346418.95 | E13: =$C$4 -> 6209078.9 | F13: =ABS(C13*D13) -> 678968.66 | G13: =E13-F13 -> 5530110.3 | H13: =E13+F13 -> 6888047.6 | N13: 0.05 | O13: =1-N13 -> 0.95 | P13: =_xlfn.NORM.S.INV(N13/2) -> -1.959964 | Q13: =$P$5/SQRT($P$3) -> 32667.594 | R13: =$P$4 -> 533698.5 | S13: =ABS(P13*Q13) -> 64027.307 | T13: =R13-S13 -> 469671.19 | U13: =R13+S13 -> 597725.81
A14: 0.01 | B14: =1-A14 -> 0.99 | C14: =_xlfn.NORM.S.INV(A14/2) -> -2.5758293 | D14: =$C$5/SQRT($C$3) -> 346418.95 | E14: =$C$4 -> 6209078.9 | F14: =ABS(C14*D14) -> 892316.08 | G14: =E14-F14 -> 5316762.9 | H14: =E14+F14 -> 7101395 | N14: 0.01 | O14: =1-N14 -> 0.99 | P14: =_xlfn.NORM.S.INV(N14/2) -> -2.5758293 | Q14: =$P$5/SQRT($P$3) -> 32667.594 | R14: =$P$4 -> 533698.5 | S14: =ABS(P14*Q14) -> 84146.145 | T14: =R14-S14 -> 449552.36 | U14: =R14+S14 -> 617844.64

Sheet Hypothesis Testing 1
F1: HYPOTHESIS TESTING 1: Pre–COVID VS Post-COVID Mean Passengers
A2: Pre-Covid Main | B2: Post-Covid Main
A3: 4546115 | B3: 4700322 | F3: Population/Sample Information | G3: Data | Q3: H0: μpre = μpost. H1: μpre ≠ μpost. This tells you it is a two‑sample, two‑tailed t‑test.
A4: 6478251 | B4: 9134970 | G4: Sample 1 size | H4: =COUNT(A3:A34) -> 32
A5: 7367068 | B5: 10444239 | G5: Sample 2 size | H5: =COUNT(B3:B16) -> 14
A6: 5282939 | B6: 8238809 | G6: Sample 1 Mean | H6: =AVERAGE(A3:A34) -> 7692378
A7: 4676120 | B7: 7622484 | G7: Sample 2 Mean | H7: =AVERAGE(B3:B16) -> 9495896.9
A8: 6747049 | B8: 10744701 | G8: Population 1 std devn | H8: =STDEV(A3:A34) -> 1910403.3 | J8: =(H6-H7)/-2.74 -> 658218.56
A9: 7719407 | B9: 11799615 | G9: Population 2 std devn | H9: =STDEV(B3:B16) -> 2099755.5
A10: 5538476 | B10: 9019601 | Q10: 0.006463 < 0.05 → Reject H0. There is strong statistical evidence that the average quarterly passenger volume for All main airports changed between the pre‑COVID and post‑COVID periods.
A11: 4804441 | B11: 8227159 | F11: Decided/Obtained by the researcher before test | G11: Significance level (𝛼) | H11: 0.05
A12: 7278735 | B12: 11231664 | G12: Hypothesised value for difference in population means | H12: 0
A13: 8219084 | B13: 12364310
A14: 6084540 | B14: 9164632 | F14: Defining the test | G14: Null Hypothesis | H14: H0:0
A15: 5541321 | B15: 8207430
A16: 8072483 | B16: 12042620 | G16: Alternative Hypothesis | H16: Ha: ≠ 0
A17: 9166638
A18: 6878352 | G18: Type of Test | H18: Two-Tailed
A19: 6419047
A20: 8814289 | F20: Computation of the test | G20: Standard Error | H20: =SQRT((H8^2/H4)+(H9^2/H7)) -> 337715.47
A21: 9989845
A22: 7518046 | G22: Test Statistic | H22: =(H6-H7)/H20 -> -5.3403502
A23: 6678744 | G23: Critical Value
A24: 9359711 | G24: Degree of Freedom | H24: =((H8^2/H4+H9^2/H5)^2)/((H8^2/H4)^2/(H4-1)+(H9^2/H5)^2/(H5-1)) -> 22.863459
A25: 10524366 | G25: p-value | H25: =_xlfn.T.DIST.2T(ABS(H22),H24) -> 2.320133e-05
A26: 7876478 | G26: Significance level (𝛼) | H26: 0.05
A27: 6939843
A28: 10031143 | F28: Test outcome and interpretation | G28: Decision | H28: Reject H0
A29: 11131101
A30: 8419046 | G30: Interpretation | H30: Data provides sufficient evidence that mean pre-COVID quarterly passengers ≠ mean post-COVID quarterly passengers for All main airports
A31: 7435673
A32: 10479523
A33: 11597270
A34: 8540952

Sheet Hypothesis Testing 2
G1: HYPOTHESIS TEST 2: Dublin vs Cork Mean Quarterly Passengers
A3: Dublin | B3: Cork | F3: Sample Information | G3: Data
A4: 3740432 | B4: 432766 | G4: Sample 1 size | H4: =COUNT(A4:A57) -> 54 | Q4: Hypotheses (one‑tailed): H0: μDublin = μCork (no difference in means). H1: μDublin > μCork (Dublin mean is higher)
A5: 5180478 | B5: 648839 | G5: Sample 2 size | H5: =COUNT(B4:B57) -> 54
A6: 5851043 | B6: 754985 | D6: P Value | G6: Sample 1 Mean | H6: =AVERAGE(A4:A57) -> 6209078.9
A7: 4318828 | B7: 497053 | D7: =_xlfn.T.TEST(A4:A57,B4:B57,1,2) -> 5.7362053e-31 | G7: Sample 2 Mean | H7: =AVERAGE(B4:B57) -> 533698.5
A8: 3874988 | B8: 436568 | G8: Sample 1 std devn | H8: =STDEV(A4:A57) -> 2545649
A9: 5460037 | B9: 634674 | G9: Sample 2 std devn | H9: =STDEV(B4:B57) -> 240056.81
A10: 6211891 | B10: 713739
A11: 4601658 | B11: 467655 | F11: Decided/Obtained by the researcher before test | G11: Significance level (𝛼) | H11: 0.05 | Q11: p‑value = 5.73621E‑31 < 0.05 → Reject H0.There is extremely strong statistical evidence that Dublin’s average quarterly passenger volume is greater than Cork’s average quarterly passenger volume.
A12: 4062698 | B12: 400785 | G12: Hypothesised value for difference in population means | H12: 0
A13: 5914826 | B13: 610996
A14: 6617238 | B14: 685538 | F14: Defining the test | G14: Null Hypothesis | H14: H0: μDublin - μCork=0
A15: 5100131 | B15: 440738
A16: 4740924 | B16: 379553 | G16: Alternative Hypothesis | H16: HA:μDublin - μCork > 0
A17: 6733056 | B17: 580130
A18: 7621339 | B18: 653801 | G18: Type of Test | H18: Right-tailed
A19: 5867199 | B19: 452194
A20: 5534979 | B20: 419334 | F20: Computation of the test | G20: Degrees of Freedom | H20: =((H8^2/H4+H9^2/H5)^2)/((H8^2/H4)^2/(H4-1)+(H9^2/H5)^2/(H5-1)) -> 53.942546
A21: 7415559 | B21: 625599 | G21: Standard Error | H21: =SQRT((H8^2/H4)+(H9^2/H5)) -> 347955.83
A22: 8361602 | B22: 706690
A23: 6466748 | B23: 474610 | G23: Test Statistic | H23: =(H6-H7)/H21 -> 16.310635
A24: 5795278 | B24: 418458 | G24: Critical Value | H24: =_xlfn.T.INV.2T(0.05,H20) -> 2.005746
A25: 7960058 | B25: 637491
A26: 8893941 | B26: 752138 | G26: p-value | H26: =_xlfn.T.DIST.2T(ABS(H23),H20) -> 2.6132032e-22
A27: 6805197 | B27: 493363 | G27: Significance level (𝛼)
A28: 6037482 | B28: 428618
A29: 8558244 | B29: 665643 | F29: Test outcome and interpretation | G29: Decision | H29: p-value (2.61E-22) < 0.05 → **REJECT H0**
A30: 9430981 | B30: 773012
A31: 7292712 | B31: 520533 | G31: Interpretation | H31: Data provides sufficient evidence that mean quarterly passengers at Dublin Airport > mean quarterly passengers at Cork Airport
A32: 6480314 | B32: 474297
A33: 8957586 | B33: 728548
A34: 9852369 | B34: 832198
A35: 7385982 | B35: 550423
A36: 5139128 | B36: 397387
A37: 155592 | B37: 7879
A38: 1270411 | B38: 90287
A39: 702109 | B39: 31461
A40: 405112 | B40: 8926
A41: 554749 | B41: 24931
...

Sheet Dublin_Regression&Correlation
A1: Time(X) | B1: Passengers | C1: X-Xbar | D1: Y-Ybar | E1: (X-Xbar)(Y-Ybar) | F1: (X-Xbar)^2 | G1: (Y-Ybar)^2 | H1: Yhat | I1: (Y-Yhat)^2 | J1: (Yhat-Ybar)^2
A2: 1 | B2: 3740432 | C2: =A2-$B$57 -> -26.5 | D2: =B2-$B$58 -> -2468646.9 | E2: =C2*D2 -> 65419144 | F2: =C2^2 -> 702.25 | G2: =D2^2 -> 6.0942177e+12 | H2: =$B$61+$B$60*A2 -> 5140229.4 | I2: =(B2-H2)^2 -> 1.9594327e+12 | J2: =(H2-$B$58)^2 -> 1.1424394e+12
A3: 2 | B3: 5180478 | C3: =A3-$B$57 -> -25.5 | D3: =B3-$B$58 -> -1028600.9 | E3: =C3*D3 -> 26229324 | F3: =C3^2 -> 650.25 | G3: =D3^2 -> 1.0580199e+12 | H3: =$B$61+$B$60*A3 -> 5180563.3 | I3: =(B3-H3)^2 -> 7282.7861 | J3: =(H3-$B$58)^2 -> 1.0578444e+12
A4: 3 | B4: 5851043 | C4: =A4-$B$57 -> -24.5 | D4: =B4-$B$58 -> -358035.94 | E4: =C4*D4 -> 8771880.6 | F4: =C4^2 -> 600.25 | G4: =D4^2 -> 1.2818974e+11 | H4: =$B$61+$B$60*A4 -> 5220897.3 | I4: =(B4-H4)^2 -> 3.9708362e+11 | J4: =(H4-$B$58)^2 -> 9.7650299e+11
A5: 4 | B5: 4318828 | C5: =A5-$B$57 -> -23.5 | D5: =B5-$B$58 -> -1890250.9 | E5: =C5*D5 -> 44420897 | F5: =C5^2 -> 552.25 | G5: =D5^2 -> 3.5730486e+12 | H5: =$B$61+$B$60*A5 -> 5261231.2 | I5: =(B5-H5)^2 -> 8.8812385e+11 | J5: =(H5-$B$58)^2 -> 8.9841529e+11
A6: 5 | B6: 3874988 | C6: =A6-$B$57 -> -22.5 | D6: =B6-$B$58 -> -2334090.9 | E6: =C6*D6 -> 52517046 | F6: =C6^2 -> 506.25 | G6: =D6^2 -> 5.4479805e+12 | H6: =$B$61+$B$60*A6 -> 5301565.2 | I6: =(B6-H6)^2 -> 2.0351224e+12 | J6: =(H6-$B$58)^2 -> 8.2358124e+11
A7: 6 | B7: 5460037 | C7: =A7-$B$57 -> -21.5 | D7: =B7-$B$58 -> -749041.94 | E7: =C7*D7 -> 16104402 | F7: =C7^2 -> 462.25 | G7: =D7^2 -> 5.6106383e+11 | H7: =$B$61+$B$60*A7 -> 5341899.1 | I7: =(B7-H7)^2 -> 1.3956559e+10 | J7: =(H7-$B$58)^2 -> 7.5200085e+11
A8: 7 | B8: 6211891 | C8: =A8-$B$57 -> -20.5 | D8: =B8-$B$58 -> 2812.0556 | E8: =C8*D8 -> -57647.139 | F8: =C8^2 -> 420.25 | G8: =D8^2 -> 7907656.4 | H8: =$B$61+$B$60*A8 -> 5382233.1 | I8: =(B8-H8)^2 -> 6.8833229e+11 | J8: =(H8-$B$58)^2 -> 6.8367411e+11
A9: 8 | B9: 4601658 | C9: =A9-$B$57 -> -19.5 | D9: =B9-$B$58 -> -1607420.9 | E9: =C9*D9 -> 31344708 | F9: =C9^2 -> 380.25 | G9: =D9^2 -> 2.5838021e+12 | H9: =$B$61+$B$60*A9 -> 5422567 | I9: =(B9-H9)^2 -> 6.738916e+11 | J9: =(H9-$B$58)^2 -> 6.1860102e+11
A10: 9 | B10: 4062698 | C10: =A10-$B$57 -> -18.5 | D10: =B10-$B$58 -> -2146380.9 | E10: =C10*D10 -> 39708047 | F10: =C10^2 -> 342.25 | G10: =D10^2 -> 4.6069512e+12 | H10: =$B$61+$B$60*A10 -> 5462901 | I10: =(B10-H10)^2 -> 1.9605683e+12 | J10: =(H10-$B$58)^2 -> 5.5678159e+11
A11: 10 | B11: 5914826 | C11: =A11-$B$57 -> -17.5 | D11: =B11-$B$58 -> -294252.94 | E11: =C11*D11 -> 5149426.5 | F11: =C11^2 -> 306.25 | G11: =D11^2 -> 8.6584795e+10 | H11: =$B$61+$B$60*A11 -> 5503234.9 | I11: =(B11-H11)^2 -> 1.6940723e+11 | J11: =(H11-$B$58)^2 -> 4.9821581e+11
A12: 11 | B12: 6617238 | C12: =A12-$B$57 -> -16.5 | D12: =B12-$B$58 -> 408159.06 | E12: =C12*D12 -> -6734624.4 | F12: =C12^2 -> 272.25 | G12: =D12^2 -> 1.6659381e+11 | H12: =$B$61+$B$60*A12 -> 5543568.8 | I12: =(B12-H12)^2 -> 1.1527655e+12 | J12: =(H12-$B$58)^2 -> 4.4290369e+11
A13: 12 | B13: 5100131 | C13: =A13-$B$57 -> -15.5 | D13: =B13-$B$58 -> -1108947.9 | E13: =C13*D13 -> 17188693 | F13: =C13^2 -> 240.25 | G13: =D13^2 -> 1.2297655e+12 | H13: =$B$61+$B$60*A13 -> 5583902.8 | I13: =(B13-H13)^2 -> 2.3403515e+11 | J13: =(H13-$B$58)^2 -> 3.9084522e+11
... A55: 54 | B55: 10017651 | C55: =A55-$B$57 -> 26.5 | D55: =B55-$B$58 -> 3808572.1 | E55: =C55*D55 -> 1.0092716e+08 | F55: =C55^2 -> 702.25 | G55: =D55^2 -> 1.4505221e+13 | H55: =$B$61+$B$60*A55 -> 7277928.5 | I55: =(B55-H55)^2 -> 7.5060794e+12 | J55: =(H55-$B$58)^2 -> 1.1424394e+12
A57: Xbar | B57: =AVERAGE(A2:A55) -> 27.5
A58: Ybar | B58: =AVERAGE(B2:B55) -> 6209078.9
A60: b1 | B60: =SUM(E2:E55)/SUM(F2:F55) -> 40333.945 | E60: Regression Equation | F60: Ŷ =5,099,895 + 40,334×Time
A61: b0 | B61: =$B$58-$B$60*$B$57 -> 5099895.4
A63: Sxy | B63: =SUM(E2:E55) -> 5.2908053e+08
A64: Sxx | B64: =SUM(F2:F55) -> 13117.5
A65: Syy/SST | B65: =SUM(G2:G55) -> 3.4345742e+14
A66: SSE | B66: =SUM(I2:I55) -> 3.2211752e+14
A67: SSR | B67: =SUM(J2:J55) -> 2.1339905e+13
A68: R2 | B68: =B67/B65 -> 0.062132607
A70: r (Correlation) | B70: =SQRT(B68) -> 0.24926413
A71: r² | B71: =B70^2 -> 0.062132607
A74: Sxy | B74: =B63 -> 5.2908053e+08
A75: Denom X √Sxx | B75: =SQRT(B64) -> 114.53166
A76: Denom Y√Syy | B76: =SQRT(B65) -> 18532604
A77: r = Num/(√Sxx×√Syy) | B77: =B74/(B75*B76) -> 0.24926413
A79: Excel Corel function | B79: =CORREL(A2:A55,B2:B55) -> 0.24926413
A81: t-stat for r | B81: =B70*SQRT(52)/(1-B70^2) -> 1.9165494
A82: df | B82: 52
A83: p-value | B83: =_xlfn.T.DIST.2T(ABS(B81),52) -> 0.060798587
A84: Significant | B84: =IF(B83<0.05,"YES","NO") -> NO
